---
title: 'C++ 模板中的异常处理'
categories:
  - [开发,cpp]
tags:
  - c++
  - cpp
---



# C++ 模板中的异常处理：从入门到进阶

在C++编程中，模板（Template）是一个非常强大的工具，它允许我们编写通用的代码，能够处理不同类型的数据。然而，随着代码复杂度的增加，异常处理（Exception Handling）也变得尤为重要。本文将带你从基础到进阶，详细讲解如何在C++模板中进行异常处理。

## 1. 什么是模板？

在开始讲解异常处理之前，我们先简单回顾一下C++模板的基本概念。

模板是C++中的一种泛型编程机制，它允许我们编写与类型无关的代码。通过模板，我们可以定义一个通用的函数或类，然后在实际使用时，编译器会根据传入的类型生成具体的代码。

### 示例：一个简单的模板函数

```cpp
#include <iostream>

// 定义一个模板函数，用于比较两个值的大小
template <typename T>
T max(T a, T b) {
    return (a > b) ? a : b;
}

int main() {
    int a = 5, b = 10;
    std::cout << "Max of " << a << " and " << b << " is " << max(a, b) << std::endl;

    double c = 3.14, d = 2.71;
    std::cout << "Max of " << c << " and " << d << " is " << max(c, d) << std::endl;

    return 0;
}
```

在这个例子中，`max` 函数是一个模板函数，它可以接受任意类型的参数，并返回较大的那个值。通过模板，我们避免了为每种类型编写重复的代码。

## 2. 异常处理基础

在C++中，异常处理是通过 `try`、`catch` 和 `throw` 关键字来实现的。当程序运行过程中发生错误时，可以通过 `throw` 抛出一个异常，然后在 `catch` 块中捕获并处理这个异常。

### 示例：一个简单的异常处理

```cpp
#include <iostream>
#include <stdexcept>

void divide(int a, int b) {
    if (b == 0) {
        throw std::runtime_error("Division by zero error");
    }
    std::cout << "Result: " << a / b << std::endl;
}

int main() {
    try {
        divide(10, 0);
    } catch (const std::exception& e) {
        std::cerr << "Exception caught: " << e.what() << std::endl;
    }

    return 0;
}
```

在这个例子中，`divide` 函数在除数为零时抛出一个 `std::runtime_error` 异常。在 `main` 函数中，我们使用 `try` 块来调用 `divide` 函数，并在 `catch` 块中捕获并处理异常。

## 3. 模板中的异常处理

在模板中进行异常处理与普通函数中的异常处理类似，但由于模板的泛型特性，我们需要特别注意一些细节。

### 3.1 模板函数中的异常处理

在模板函数中，异常处理的基本原理与普通函数相同。我们可以在模板函数中抛出异常，并在调用模板函数时捕获异常。

#### 示例：模板函数中的异常处理

```cpp
#include <iostream>
#include <stdexcept>

// 定义一个模板函数，用于安全地进行除法运算
template <typename T>
T safe_divide(T a, T b) {
    if (b == 0) {
        throw std::runtime_error("Division by zero error");
    }
    return a / b;
}

int main() {
    try {
        double result = safe_divide(10.0, 0.0);
        std::cout << "Result: " << result << std::endl;
    } catch (const std::exception& e) {
        std::cerr << "Exception caught: " << e.what() << std::endl;
    }

    return 0;
}
```

在这个例子中，`safe_divide` 是一个模板函数，它接受两个参数并进行除法运算。如果除数为零，函数会抛出一个 `std::runtime_error` 异常。在 `main` 函数中，我们使用 `try` 块来调用 `safe_divide` 函数，并在 `catch` 块中捕获并处理异常。

### 3.2 模板类中的异常处理

在模板类中，异常处理的方式与模板函数类似。我们可以在模板类的成员函数中抛出异常，并在调用这些成员函数时捕获异常。

#### 示例：模板类中的异常处理

```cpp
#include <iostream>
#include <stdexcept>
#include <vector>

// 定义一个模板类，用于管理一个动态数组
template <typename T>
class DynamicArray {
private:
    std::vector<T> data;

public:
    void add(T value) {
        data.push_back(value);
    }

    T get(size_t index) {
        if (index >= data.size()) {
            throw std::out_of_range("Index out of range");
        }
        return data[index];
    }
};

int main() {
    try {
        DynamicArray<int> arr;
        arr.add(10);
        arr.add(20);
        std::cout << "Element at index 1: " << arr.get(1) << std::endl;
        std::cout << "Element at index 2: " << arr.get(2) << std::endl; // 这里会抛出异常
    } catch (const std::exception& e) {
        std::cerr << "Exception caught: " << e.what() << std::endl;
    }

    return 0;
}
```

在这个例子中，`DynamicArray` 是一个模板类，它使用 `std::vector` 来管理一个动态数组。`get` 成员函数在访问数组元素时，如果索引超出范围，会抛出一个 `std::out_of_range` 异常。在 `main` 函数中，我们使用 `try` 块来调用 `get` 函数，并在 `catch` 块中捕获并处理异常。

### 3.3 模板中的异常类型推导

在模板中，异常类型的推导是一个需要注意的问题。由于模板是泛型的，异常类型可能会有所不同，因此我们需要确保捕获的异常类型是通用的。

#### 示例：模板中的异常类型推导

```cpp
#include <iostream>
#include <stdexcept>

// 定义一个模板函数，用于进行某种操作，可能会抛出不同类型的异常
template <typename T>
void do_something(T value) {
    if (value < 0) {
        throw std::invalid_argument("Value cannot be negative");
    } else if (value == 0) {
        throw std::logic_error("Value cannot be zero");
    }
    std::cout << "Value is valid: " << value << std::endl;
}

int main() {
    try {
        do_something(-1); // 这里会抛出 std::invalid_argument 异常
        do_something(0);  // 这里会抛出 std::logic_error 异常
    } catch (const std::invalid_argument& e) {
        std::cerr << "Invalid argument exception caught: " << e.what() << std::endl;
    } catch (const std::logic_error& e) {
        std::cerr << "Logic error exception caught: " << e.what() << std::endl;
    } catch (const std::exception& e) {
        std::cerr << "Generic exception caught: " << e.what() << std::endl;
    }

    return 0;
}
```

在这个例子中，`do_something` 是一个模板函数，它根据传入的值抛出不同类型的异常。在 `main` 函数中，我们使用多个 `catch` 块来捕获不同类型的异常。通过这种方式，我们可以确保在模板中处理不同类型的异常。

## 4. 进阶：模板中的异常安全

在复杂的模板代码中，异常安全（Exception Safety）是一个非常重要的话题。异常安全指的是在抛出异常时，程序的状态仍然保持一致，不会出现资源泄漏或数据损坏等问题。

### 4.1 基本异常安全保证

在C++中，异常安全通常分为三个级别：

1. **基本保证**：如果异常被抛出，程序的状态不会变得不一致，但可能会有一些副作用。
2. **强保证**：如果异常被抛出，程序的状态会恢复到调用操作之前的状态，没有任何副作用。
3. **无抛出保证**：操作永远不会抛出异常。

#### 示例：模板中的基本异常安全保证

```cpp
#include <iostream>
#include <stdexcept>
#include <vector>

// 定义一个模板类，用于管理一个动态数组，并提供基本异常安全保证
template <typename T>
class SafeDynamicArray {
private:
    std::vector<T> data;

public:
    void add(T value) {
        data.push_back(value); // 这里可能会抛出异常，但不会导致数据损坏
    }

    T get(size_t index) {
        if (index >= data.size()) {
            throw std::out_of_range("Index out of range");
        }
        return data[index];
    }
};

int main() {
    try {
        SafeDynamicArray<int> arr;
        arr.add(10);
        arr.add(20);
        std::cout << "Element at index 1: " << arr.get(1) << std::endl;
        std::cout << "Element at index 2: " << arr.get(2) << std::endl; // 这里会抛出异常
    } catch (const std::exception& e) {
        std::cerr << "Exception caught: " << e.what() << std::endl;
    }

    return 0;
}
```

在这个例子中，`SafeDynamicArray` 类提供了基本异常安全保证。即使 `add` 函数在向 `std::vector` 中添加元素时抛出异常，程序的状态仍然是安全的，不会导致数据损坏。

### 4.2 强异常安全保证

在某些情况下，我们可能需要提供强异常安全保证，即在抛出异常时，程序的状态会恢复到操作之前的状态。

#### 示例：模板中的强异常安全保证

```cpp
#include <iostream>
#include <stdexcept>
#include <vector>

// 定义一个模板类，用于管理一个动态数组，并提供强异常安全保证
template <typename T>
class StrongSafeDynamicArray {
private:
    std::vector<T> data;

public:
    void add(T value) {
        size_t old_size = data.size(); // 记录操作前的状态
        data.push_back(value); // 这里可能会抛出异常
        if (data.size() != old_size + 1) {
            data.resize(old_size); // 如果操作失败，恢复到之前的状态
            throw std::runtime_error("Failed to add element");
        }
    }

    T get(size_t index) {
        if (index >= data.size()) {
            throw std::out_of_range("Index out of range");
        }
        return data[index];
    }
};

int main() {
    try {
        StrongSafeDynamicArray<int> arr;
        arr.add(10);
        arr.add(20);
        std::cout << "Element at index 1: " << arr.get(1) << std::endl;
        std::cout << "Element at index 2: " << arr.get(2) << std::endl; // 这里会抛出异常
    } catch (const std::exception& e) {
        std::cerr << "Exception caught: " << e.what() << std::endl;
    }

    return 0;
}
```

在这个例子中，`StrongSafeDynamicArray` 类提供了强异常安全保证。在 `add` 函数中，我们记录了操作前的状态，并在操作失败时恢复到之前的状态。通过这种方式，我们确保了在抛出异常时，程序的状态不会变得不一致。

## 5. 总结

在C++模板中进行异常处理是一个非常重要的话题。通过本文的讲解，我们了解了如何在模板函数和模板类中进行异常处理，并探讨了异常安全的基本概念。

- **模板函数中的异常处理**：与普通函数类似，可以在模板函数中抛出异常，并在调用时捕获异常。
- **模板类中的异常处理**：在模板类的成员函数中抛出异常，并在调用时捕获异常。
- **异常安全**：在复杂的模板代码中，异常安全是一个需要特别注意的问题。我们可以通过提供基本或强异常安全保证来确保程序的状态在抛出异常时仍然保持一致。

文章合集：[chongzicbo/ReadWriteThink: 博学而笃志，切问而近思 (github.com)](https://github.com/chongzicbo/ReadWriteThink/tree/main)

个人博客：[程博仕](https://chongzicbo.github.io/)

微信公众号：

![微信公众号](https://raw.githubusercontent.com/chongzicbo/images/main/picgo/%E4%BA%8C%E7%BB%B4%E7%A0%81.jpg)