# C++异常处理

## 1. 引言

### 1.1 什么是异常处理
异常处理是一种编程技术，用于在程序运行过程中处理错误或异常情况。异常处理机制允许程序在遇到错误时，能够以一种结构化的方式处理这些错误，而不是简单地崩溃或终止。

### 1.2 为什么需要异常处理
在程序运行过程中，可能会遇到各种不可预见的错误，如除零错误、内存分配失败、文件读取错误等。如果没有异常处理机制，程序可能会直接崩溃或产生不可预测的行为。异常处理提供了一种优雅的方式来处理这些错误，使得程序能够继续运行或以可控的方式终止。

### 1.3 C++异常处理的基本概念
C++异常处理机制基于三个关键字：`try`、`catch`和`throw`。`try`块用于包裹可能抛出异常的代码，`catch`块用于捕获并处理异常，`throw`语句用于显式地抛出异常。

## 2. C++异常处理的基础

### 2.1 `try`块

#### 2.1.1 代码示例
```cpp
#include <iostream>

int main() {
    try {
        std::cout << "Inside try block" << std::endl;
        throw 10; // 抛出一个整数异常
    }
    catch (int e) {
        std::cout << "Caught exception: " << e << std::endl;
    }
    return 0;
}
```

#### 2.1.2 代码解析
- `try`块用于包裹可能抛出异常的代码。
- 在`try`块中，如果发生异常（如`throw 10;`），程序将立即跳转到`catch`块。
- `catch`块用于捕获并处理异常。在这个例子中，`catch (int e)`捕获了一个整数类型的异常，并输出异常的值。

### 2.2 `catch`块

#### 2.2.1 代码示例
```cpp
#include <iostream>

int main() {
    try {
        std::cout << "Inside try block" << std::endl;
        throw "Exception"; // 抛出一个字符串异常
    }
    catch (const char* e) {
        std::cout << "Caught exception: " << e << std::endl;
    }
    return 0;
}
```

#### 2.2.2 代码解析
- `catch`块用于捕获并处理异常。
- 在这个例子中，`catch (const char* e)`捕获了一个字符串类型的异常，并输出异常的内容。
- `catch(const)`关键字是为了确保捕获的异常对象在`catch`块中是**只读的**，即不会被修改。
  - **安全性**：防止在`catch`块中意外修改异常对象的值，避免潜在的逻辑错误。
  - **可读性**：明确表示异常对象是只读的，便于其他开发者理解代码意图。
  - **一致性**：如果异常对象本身是`const`类型，那么捕获时也必须使用`const`来匹配。

- `catch`块可以有多个，用于捕获不同类型的异常。

### 2.3 `throw`语句

#### 2.3.1 代码示例
```cpp
#include <iostream>

void throwException() {
    std::cout << "Throwing exception" << std::endl;
    throw 20.5; // 抛出一个浮点数异常
}

int main() {
    try {
        throwException();
    }
    catch (double e) {
        std::cout << "Caught exception: " << e << std::endl;
    }
    return 0;
}
```

#### 2.3.2 代码解析
- `throw`语句用于显式地抛出异常。
- 在这个例子中，`throw 20.5;`抛出了一个浮点数类型的异常。
- `catch (double e)`捕获了这个异常，并输出异常的值。

### 2.4 异常处理的流程

#### 2.4.1 代码示例
```cpp
#include <iostream>

void func1() {
    std::cout << "Inside func1" << std::endl;
    throw "Exception from func1";
}

void func2() {
    std::cout << "Inside func2" << std::endl;
    func1();
}

int main() {
    try {
        func2();
    }
    catch (const char* e) {
        std::cout << "Caught exception: " << e << std::endl;
    }
    return 0;
}
```

#### 2.4.2 代码解析
- 异常处理的流程是从`throw`语句开始，沿着调用栈向上传播，直到找到匹配的`catch`块。
- 在这个例子中，`func1`抛出了一个异常，`func2`调用了`func1`，`main`函数中的`try`块调用了`func2`。
- 异常从`func1`传播到`func2`，再到`main`函数中的`catch`块。

## 3. 异常类型

### 3.1 内置异常类型

#### 3.1.1 `std::exception`
`std::exception`是C++标准库中所有异常的基类。它定义了一个虚函数`what()`，用于返回异常的描述信息。

```cpp
#include <iostream>
#include <exception>

int main() {
    try {
        throw std::exception();
    }
    catch (const std::exception& e) {
        std::cout << "Caught exception: " << e.what() << std::endl;
    }
    return 0;
}
```

#### 3.1.2 其他内置异常类型
C++标准库还提供了其他一些内置异常类型，如`std::bad_alloc`、`std::runtime_error`等。

```cpp
#include <iostream>
#include <stdexcept>

int main() {
    try {
        throw std::runtime_error("Runtime error occurred");
    }
    catch (const std::runtime_error& e) {
        std::cout << "Caught exception: " << e.what() << std::endl;
    }
    return 0;
}
```

### 3.2 自定义异常类型

#### 3.2.1 代码示例
```cpp
#include <iostream>
#include <exception>

class MyException : public std::exception {
public:
    const char* what() const noexcept override {
        return "My custom exception";
    }
};

int main() {
    try {
        throw MyException();
    }
    catch (const MyException& e) {
        std::cout << "Caught exception: " << e.what() << std::endl;
    }
    return 0;
}
```

#### 3.2.2 代码解析
- 自定义异常类型通常继承自`std::exception`。
- 在这个例子中，`MyException`继承自`std::exception`，并重写了`what()`函数，返回自定义的异常描述信息。
- `catch (const MyException& e)`捕获了这个自定义异常，并输出异常的描述信息。

## 4. 异常处理的进阶

### 4.1 异常的传播

#### 4.1.1 代码示例
```cpp
#include <iostream>

void func1() {
    std::cout << "Inside func1" << std::endl;
    throw "Exception from func1";
}

void func2() {
    std::cout << "Inside func2" << std::endl;
    try {
        func1();
    }
    catch (const char* e) {
        std::cout << "Caught exception in func2: " << e << std::endl;
        throw; // 重新抛出异常
    }
}

int main() {
    try {
        func2();
    }
    catch (const char* e) {
        std::cout << "Caught exception in main: " << e << std::endl;
    }
    return 0;
}
```

#### 4.1.2 代码解析
- 异常可以在函数内部捕获并处理，然后重新抛出，继续传播。
- 在这个例子中，`func2`捕获了`func1`抛出的异常，并重新抛出。
- `main`函数中的`catch`块最终捕获了这个异常。

### 4.2 异常的重新抛出

#### 4.2.1 代码示例
```cpp
#include <iostream>

void func1() {
    std::cout << "Inside func1" << std::endl;
    throw "Exception from func1";
}

void func2() {
    std::cout << "Inside func2" << std::endl;
    try {
        func1();
    }
    catch (const char* e) {
        std::cout << "Caught exception in func2: " << e << std::endl;
        throw; // 重新抛出异常
    }
}

int main() {
    try {
        func2();
    }
    catch (const char* e) {
        std::cout << "Caught exception in main: " << e << std::endl;
    }
    return 0;
}
```

#### 4.2.2 代码解析
- `throw;`语句用于重新抛出当前捕获的异常。
- 在这个例子中，`func2`捕获了`func1`抛出的异常，并重新抛出。
- `main`函数中的`catch`块最终捕获了这个异常。

### 4.3 异常处理的性能考虑

#### 4.3.1 代码示例
```cpp
#include <iostream>
#include <chrono>

void func1() {
    std::cout << "Inside func1" << std::endl;
    throw "Exception from func1";
}

void func2() {
    std::cout << "Inside func2" << std::endl;
    try {
        func1();
    }
    catch (const char* e) {
        std::cout << "Caught exception in func2: " << e << std::endl;
        throw; // 重新抛出异常
    }
}

int main() {
    auto start = std::chrono::high_resolution_clock::now();
    try {
        func2();
    }
    catch (const char* e) {
        std::cout << "Caught exception in main: " << e << std::endl;
    }
    auto end = std::chrono::high_resolution_clock::now();
    std::chrono::duration<double> elapsed = end - start;
    std::cout << "Elapsed time: " << elapsed.count() << " seconds" << std::endl;
    return 0;
}
```

#### 4.3.2 代码解析
- 异常处理可能会带来性能开销，特别是在异常频繁发生的情况下。
- 在这个例子中，我们使用`std::chrono`来测量异常处理的执行时间。
- 异常处理的性能开销主要来自于异常的传播和栈的展开。

## 5. 异常处理的注意事项

### 5.1 异常安全性

#### 5.1.1 代码示例
```cpp
#include <iostream>
#include <memory>

class Resource {
public:
    Resource() { std::cout << "Resource acquired" << std::endl; }
    ~Resource() { std::cout << "Resource released" << std::endl; }
};

void func1() {
    std::unique_ptr<Resource> res(new Resource());
    std::cout << "Inside func1" << std::endl;
    throw "Exception from func1";
}

int main() {
    try {
        func1();
    }
    catch (const char* e) {
        std::cout << "Caught exception: " << e << std::endl;
    }
    return 0;
}
```

#### 5.1.2 代码解析
- 异常安全性是指在异常发生时，程序能够保持一致的状态，不会出现资源泄漏或数据损坏。
- 在这个例子中，我们使用`std::unique_ptr`来自动管理资源的生命周期，确保在异常发生时资源能够正确释放。

### 5.2 资源管理与异常

#### 5.2.1 代码示例
```cpp
#include <iostream>
#include <memory>

class Resource {
public:
    Resource() { std::cout << "Resource acquired" << std::endl; }
    ~Resource() { std::cout << "Resource released" << std::endl; }
};

void func1() {
    std::unique_ptr<Resource> res(new Resource());
    std::cout << "Inside func1" << std::endl;
    throw "Exception from func1";
}

int main() {
    try {
        func1();
    }
    catch (const char* e) {
        std::cout << "Caught exception: " << e << std::endl;
    }
    return 0;
}
```

#### 5.2.2 代码解析
- 在异常处理中，资源管理是一个重要的考虑因素。
- 使用智能指针（如`std::unique_ptr`）可以自动管理资源的生命周期，避免资源泄漏。

### 5.3 异常处理的替代方案

#### 5.3.1 代码示例
```cpp
#include <iostream>

int divide(int a, int b) {
    if (b == 0) {
        return -1; // 返回错误码
    }
    return a / b;
}

int main() {
    int result = divide(10, 0);
    if (result == -1) {
        std::cout << "Error: Division by zero" << std::endl;
    } else {
        std::cout << "Result: " << result << std::endl;
    }
    return 0;
}
```

#### 5.3.2 代码解析
- 异常处理的替代方案包括返回错误码、使用状态标志等。
- 在这个例子中，`divide`函数在除零时返回`-1`作为错误码，`main`函数检查返回值并处理错误。
- 这种方法适用于简单的错误处理，但在复杂的程序中可能会导致代码的可读性和维护性下降。

## 6. 总结

### 6.1 异常处理的优点
- 异常处理提供了一种结构化的错误处理机制，使得程序能够在遇到错误时以可控的方式处理。
- 异常处理使得错误处理代码与正常业务逻辑分离，提高了代码的可读性和维护性。

### 6.2 异常处理的缺点
- 异常处理可能会带来性能开销，特别是在异常频繁发生的情况下。
- 异常处理可能会导致资源泄漏或数据损坏，需要特别注意异常安全性。

### 6.3 何时使用异常处理
- 异常处理适用于处理不可预见的错误或异常情况。
- 在需要处理复杂错误场景或需要保证程序一致性的情况下，异常处理是一个很好的选择。

